Greetings, esteemed developer! 👨‍💻  Let us now confront the inevitable aspect of programming – **"Errors and Exceptions"**.  Think of errors and exceptions as the **"alert system 🚨 and fault handling mechanisms 🛠️" of your Python programs**. They are critical for robustness, providing ways to detect, manage, and gracefully recover from unexpected situations during program execution.

Imagine errors and exceptions as the **"diagnostic panel 🩺 and emergency protocols 🚑" for a complex machine (your program)**.  They help you identify problems (errors), understand their nature (exceptions), and implement procedures to handle them effectively, preventing crashes and ensuring smooth operation.

## 8. Errors and Exceptions

This section provides a comprehensive understanding of error types in Python, how exceptions occur, and the mechanisms Python offers to handle them, ensuring your programs are resilient and well-behaved. It's about mastering the art of error management and building robust applications.

### 8.1. Syntax Errors

**Syntax errors**, also known as **parsing errors**, are the most basic type of error. They occur when Python encounters code that violates the grammatical rules (syntax) of the Python language.  Think of syntax errors as **"grammatical mistakes ✍️ in your code"** that prevent Python from understanding your instructions.

**Analogy: Syntax Errors as Grammatical Mistakes ✍️**

Imagine writing a sentence in English. If you make a grammatical mistake, like forgetting a verb or using incorrect word order, the sentence becomes ungrammatical and hard to understand. Syntax errors in Python are similar – they are like ungrammatical sentences in code that Python cannot parse.

**Examples of Syntax Errors:**

*   **Missing colon `:` at the end of a statement:**

    ```python
    if True  # Missing colon
        print("Hello")
    ```
    *SyntaxError: invalid syntax*

*   **Misspelled keyword:**

    ```python
    whille True:  # Misspelled 'while'
        print("Looping")
    ```
    *SyntaxError: invalid syntax*

*   **Unmatched parentheses `()` or brackets `[]` or braces `{}`:**

    ```python
    my_list = [1, 2, 3  # Unclosed bracket
    print(my_list)
    ```
    *SyntaxError: unexpected EOF while parsing*

**Detection and Handling:**

*   **Detected during parsing:** Syntax errors are detected by the Python interpreter *before* the program actually runs, during the parsing or compilation phase.
*   **Reported immediately:** Python immediately reports a `SyntaxError` and usually indicates the line number and sometimes the location of the error.
*   **Must be fixed to run the code:** Syntax errors must be corrected before the Python interpreter can successfully execute the program.  They are not something that can be "handled" at runtime; they must be fixed at the code writing stage.

**Diagrammatic Representation of Syntax Errors:**

```
[Syntax Errors - Grammatical Mistakes] ✍️
    ├── Violation of Python language syntax rules. 🚫📜
    ├── Detected during parsing/compilation. 🔍
    ├── Reported as SyntaxError with line number and location. 🚨
    └── Must be fixed before program execution. ✅🛠️

[Analogy - Ungrammatical Sentence] ✍️❌
    Example: "I is go to store."  <- Ungrammatical English
             if True  <- Ungrammatical Python (missing colon)

[Example Syntax Errors]
    ├── Missing colon: if condition  -> SyntaxError: invalid syntax
    ├── Misspelled keyword: whille -> SyntaxError: invalid syntax
    └── Unmatched brackets: [1, 2   -> SyntaxError: unexpected EOF while parsing
```

**Emoji Summary for Syntax Errors:** ✍️ Grammatical mistake,  🚫📜 Syntax violation,  🔍 Parsing detection,  🚨 SyntaxError report,  ✅🛠️ Must be fixed,  ❌ Runtime execution blocked.

### 8.2. Exceptions

**Exceptions** occur during program execution (runtime) when something goes wrong that Python cannot normally handle. These are events that disrupt the normal flow of the program. Think of exceptions as **"runtime surprises or unexpected events 💥"** that happen while your program is running.

**Analogy: Exceptions as Runtime Surprises 💥**

Imagine driving a car. You follow traffic rules (syntax is correct). However, during your drive (runtime), unexpected events can occur:

*   **Flat tire 🛞💥:**  A `TypeError` if you try to perform an operation on an incompatible data type.
*   **Running out of fuel ⛽🚫:** A `FileNotFoundError` if you try to open a file that doesn't exist.
*   **Getting lost 🗺️❓:** A `NameError` if you try to use a variable that hasn't been defined.
*   **Division by zero ➗0️⃣:** A `ZeroDivisionError` if you attempt to divide by zero.

These are runtime problems (exceptions) that are different from grammatical mistakes (syntax errors).

**Examples of Exceptions:**

*   **`TypeError`:**  Occurs when an operation or function is applied to an object of inappropriate type.

    ```python
    result = "5" + 3  # Trying to add a string and an integer
    ```
    *TypeError: can only concatenate str (not "int") to str*

*   **`FileNotFoundError`:** Occurs when a file or directory is requested but cannot be found.

    ```python
    with open("non_existent_file.txt", "r") as f: # Trying to open a file that doesn't exist
        content = f.read()
    ```
    *FileNotFoundError: [Errno 2] No such file or directory: 'non_existent_file.txt'*

*   **`NameError`:** Occurs when you try to use a variable that has not been assigned a value.

    ```python
    print(undefined_variable) # Using a variable that is not defined
    ```
    *NameError: name 'undefined_variable' is not defined*

*   **`ZeroDivisionError`:** Occurs when you try to divide a number by zero.

    ```python
    result = 10 / 0  # Division by zero
    ```
    *ZeroDivisionError: division by zero*

**Characteristics of Exceptions:**

*   **Occur at runtime:** Exceptions happen while the program is executing, not during parsing.
*   **Disrupt normal flow:** Exceptions interrupt the normal sequential execution of code.
*   **Can be handled:** Python provides mechanisms to "catch" and "handle" exceptions, preventing program termination and allowing for graceful error recovery.
*   **Represent different error conditions:** Different types of exceptions represent different kinds of runtime problems (e.g., `TypeError`, `ValueError`, `IndexError`, `KeyError`, etc.).

**Diagrammatic Representation of Exceptions:**

```
[Exceptions - Runtime Surprises] 💥
    ├── Runtime errors that disrupt normal program flow. 🛑
    ├── Occur during program execution (not parsing). 🏃‍♂️💨
    ├── Represent various error conditions (e.g., TypeError, FileNotFoundError). ⚠️
    └── Can be handled to prevent program crash. ✅🛠️

[Analogy - Unexpected Events While Driving] 💥🚗
    Flat tire 🛞💥 -> TypeError (incompatible operation)
    No fuel ⛽🚫  -> FileNotFoundError (resource not found)
    Lost map 🗺️❓ -> NameError (undefined name)
    Zero speed ➗0️⃣ -> ZeroDivisionError (math error)

[Example Exception Types]
    ├── TypeError: Incompatible type operation. 🔤❌
    ├── FileNotFoundError: File or directory not found. 📄❌
    ├── NameError: Undefined variable name. 🏷️❌
    └── ZeroDivisionError: Division by zero. ➗0️⃣❌
```

**Emoji Summary for Exceptions:** 💥 Runtime surprise,  🛑 Flow disruption,  🏃‍♂️💨 Runtime occurrence,  ⚠️ Error conditions,  ✅🛠️ Can be handled,  🛞💥 TypeError,  ⛽🚫 FileNotFoundError,  🗺️❓ NameError,  ➗0️⃣ ZeroDivisionError.

### 8.3. Handling Exceptions

Python provides the **`try...except` block** to handle exceptions. This allows you to "try" a block of code that might raise an exception, and if an exception occurs, "except" it and execute specific code to handle it gracefully.  Think of `try...except` as **"error interception and recovery protocols 🛠️🚑"**.

**`try...except` Block Structure:**

```python
try:
    # Code that might raise an exception (risky code)
    statement1
    statement2
    ...
except ExceptionType1:
    # Code to handle ExceptionType1 (error handling block 1)
    handler_statement1
    handler_statement2
    ...
except ExceptionType2: # Optional, can have multiple except blocks
    # Code to handle ExceptionType2 (error handling block 2)
    handler_statement3
    handler_statement4
    ...
except: # Optional, bare except, catches all exceptions not caught by previous except blocks
    # Code to handle any other exception (general handler)
    default_handler_statement1
    ...
else: # Optional, executed if NO exception occurred in try block
    # Code to execute if try block completed successfully (no exceptions)
    else_statement1
    ...
finally: # Optional, always executed, regardless of exception or not
    # Code to execute for cleanup actions (always runs)
    finally_statement1
    ...
```

**Key Components:**

*   **`try` block:**  Encloses the code that you want to monitor for exceptions.
*   **`except ExceptionType:`:**  Specifies the type of exception to catch and handle. You can have multiple `except` blocks to handle different exception types.
*   **`except:` (bare except):** Catches all exceptions that are not caught by preceding specific `except` blocks. Use with caution, as it can hide unexpected errors.
*   **`else` block (optional):**  Executed *only if* the `try` block completes without raising any exceptions. Useful for code that should run after successful execution of the `try` block.
*   **`finally` block (optional):**  Always executed, whether an exception occurred in the `try` block or not, and whether the exception was handled or not.  Typically used for cleanup actions (e.g., closing files, releasing resources).

**Analogy: `try...except` as Error Interception and Recovery 🛠️🚑**

Imagine `try...except` as setting up error interception and recovery protocols for a risky operation (like a delicate surgery 🩺):

1.  **`try:` (Start Risky Operation):** "Try to perform this operation (risky code) carefully."
2.  **`except ExceptionType:` (If Specific Problem Occurs):** "If a *specific type of problem* (ExceptionType) occurs during the operation, execute this *specific recovery procedure* (handler block)." (Multiple `except` blocks for different problem types).
3.  **`except:` (If Any Other Problem):** "If *any other unexpected problem* occurs, execute this *general emergency procedure* (bare except handler)." (Use sparingly, like a last resort).
4.  **`else:` (If Operation Successful):** "If the operation completes *successfully without any problems*, perform these *post-operation steps* (else block)."
5.  **`finally:` (Cleanup Actions - Always):** "Regardless of whether the operation was successful or if problems occurred, perform these *cleanup actions* (finally block) *afterwards*." (Like sterilizing instruments and cleaning up the operating room 🚑 after surgery, no matter the outcome).

**Example Handling `ZeroDivisionError`:**

```python
def divide(x, y):
    try:
        result = x / y
    except ZeroDivisionError:
        print("Error: Division by zero!")
        result = None # Set result to None in case of error
    else:
        print("Division successful.") # Executed if no ZeroDivisionError
    finally:
        print("This always executes, regardless of errors.") # Cleanup action
    return result

print(divide(10, 2)) # Output: Division successful., This always executes..., 5.0
print(divide(10, 0)) # Output: Error: Division by zero!, This always executes..., None
```

**Flowchart Representation of `try...except...finally`:**

```mermaid
graph LR
    A[Start try block] --> B{Exception in try block?};
    B -- Yes --> C{Match except ExceptionType1?};
    C -- Yes --> D[Execute except ExceptionType1 block];
    C -- No --> E{Match except ExceptionType2?};
    E -- Yes --> F[Execute except ExceptionType2 block];
    E -- No --> G{Match bare except?};
    G -- Yes --> H[Execute bare except block];
    G -- No --> I[Exception not handled, propagate upwards];
    B -- No --> J[Execute else block (if present)];
    D --> K[Execute finally block (if present)];
    F --> K;
    H --> K;
    J --> K;
    I --> K;
    K --> L[End try...except...finally];
```

**Emoji Summary for `try...except`:** 🛠️🚑 Error handling,  try Risky code,  except Catch specific error,  except: Catch all,  else No error,  finally Always execute,  ✅ Graceful recovery,  🛡️ Prevent crash.

### 8.4. Raising Exceptions

You can **raise exceptions intentionally** in your code using the `raise` statement. This is useful for signaling error conditions, validating input, or indicating that a certain situation is not expected or supported.  Think of `raise` as **"sounding an alarm 🚨"** in your program to signal a problem.

**`raise` Statement Syntax:**

```python
raise ExceptionType("Error message")
```

*   **`raise` keyword:**  Initiates the raising of an exception.
*   **`ExceptionType`:** The type of exception you want to raise (e.g., `ValueError`, `TypeError`, `RuntimeError`, or a user-defined exception).
*   **`"Error message"` (optional):**  A string providing a descriptive error message to accompany the exception, which can be helpful for debugging.

**Analogy: `raise` as Sounding an Alarm 🚨**

Imagine you are monitoring a system. If you detect an abnormal or unacceptable condition, you sound an alarm to alert others and initiate error handling procedures. `raise` statement is like sounding an alarm in your code:

1.  **Detect Error Condition:** Your code detects a problem (e.g., invalid input, unexpected state).
2.  **`raise ExceptionType("Error message")` (Sound Alarm):** You use `raise` to trigger an exception, sounding an alarm.
3.  **Exception Handling (Error Response):** The `try...except` blocks (error handling protocols) in your program or calling code can then intercept this alarm and handle the situation.

**Examples of Raising Exceptions:**

*   **Raising `ValueError` for invalid input:**

    ```python
    def get_age(age_str):
        try:
            age = int(age_str)
            if age < 0:
                raise ValueError("Age cannot be negative") # Raise ValueError if age is negative
            return age
        except ValueError as e:
            print(f"Invalid age input: {e}")
            return None

    user_age = get_age(input("Enter your age: ")) # User might enter invalid age
    if user_age is not None:
        print(f"User age: {user_age}")
    ```

*   **Raising `NotImplementedError` for abstract methods in base classes:**

    ```python
    class Shape:
        def area(self):
            raise NotImplementedError("Subclasses must implement area method") # Abstract method
        def perimeter(self):
            raise NotImplementedError("Subclasses must implement perimeter method")

    class Circle(Shape):
        def area(self):
            return 3.14 * self.radius**2

    shape = Shape()
    # shape.area() # This will raise NotImplementedError
    circle = Circle()
    circle.area() # This will work, as Circle implements area()
    ```

**Diagrammatic Representation of Raising Exceptions:**

```
[Raising Exceptions - Sounding an Alarm] 🚨
    ├── raise ExceptionType("Error message"):  Trigger an exception intentionally. 🚨
    ├── Signal error conditions, invalid input, unsupported situations. ⚠️
    ├── Triggers exception handling mechanisms (try...except blocks). 🛠️🚑
    └── Analogy: Sounding an alarm to indicate a problem. 🚨🔊

[Example - Raising ValueError]
    def get_age(age_str):
        age = int(age_str)
        if age < 0:
            raise ValueError("Age cannot be negative")  <- Raise exception here
        return age

[Example - Raising NotImplementedError]
    class Shape:
        def area(self):
            raise NotImplementedError("Subclasses must implement area") <- Raise exception for abstract method
```

**Emoji Summary for Raising Exceptions:** 🚨 Sound alarm,  ⚠️ Signal error,  🛠️🚑 Trigger error handling,  raise Statement,  ExceptionType Error type,  "Message" Error description,  🔊 Alert problem.

### 8.5. Exception Chaining

**Exception chaining** (or exception context) allows you to link together exceptions that occur in a sequence, providing more context and debugging information when errors are nested or related.  Think of exception chaining as **"linking error messages like a chain 🔗"** to show the sequence of failures leading to a problem.

**Mechanism of Exception Chaining:**

When an exception occurs inside an `except` block, and you `raise` a new exception from within that `except` block, Python automatically chains the new exception to the original exception. This means the new exception will carry information about the original exception that caused it.

**Implicit Chaining (Automatic):**

By default, when you `raise` a new exception inside an `except` block, Python performs implicit chaining. The original exception becomes the `__context__` attribute of the new exception.

**Explicit Chaining using `raise ... from ...`:**

You can explicitly control exception chaining using the `raise ... from ...` syntax:

```python
try:
    # Code that might raise original_exception
    risky_operation()
except OriginalException as original_exc:
    # Handle OriginalException, and then raise a new exception
    raise NewException("Problem in handling original") from original_exc # Explicit chaining
    # or
    raise NewException("Problem in handling original") # Implicit chaining (if 'from original_exc' is omitted)
```

*   **`raise NewException(...) from original_exc` (Explicit):**  Explicitly sets `original_exc` as the cause of `NewException`. The `__cause__` attribute of `NewException` will be set to `original_exc`.
*   **`raise NewException(...)` (Implicit):** If `from` clause is omitted inside an `except` block, the caught exception (`original_exc` in the example) becomes the `__context__` of `NewException`.

**`__cause__` vs. `__context__`:**

*   **`__cause__`:** Indicates a *direct* cause – the exception that directly led to the current exception. Set using `raise ... from ...`. Indicates *deliberate* chaining.
*   **`__context__`:** Indicates a *contextual* relationship – the exception that was being handled when the current exception occurred. Set implicitly when raising within an `except` block without `from`. Indicates *automatic* chaining in exception handlers.

**Analogy: Exception Chaining as Linking Error Messages 🔗**

Imagine exception chaining like linking error messages together to trace the root cause of a problem:

1.  **Original Error (First Link):**  An initial problem occurs (e.g., file not found - `FileNotFoundError`).
2.  **Handling Error, New Error (Second Link):** While trying to handle the original error, a new problem occurs (e.g., problem processing error message file - `IOError`).
3.  **Chaining (Linking Errors):**  Exception chaining links the `IOError` to the original `FileNotFoundError`, showing that the `IOError` happened *because* of the attempt to handle the `FileNotFoundError`. It's like forming a chain of error messages 🔗 to show the sequence of failures.

**Example of Exception Chaining:**

```python
def process_file(filename):
    try:
        with open(filename, 'r') as f:
            data = f.read()
            process_data(data) # Might raise ValueError if data is invalid
    except FileNotFoundError as e:
        raise RuntimeError(f"Failed to process file: {filename}") from e # Explicit chaining

def process_data(data):
    if not data.isdigit():
        raise ValueError("Data is not numeric") # Original exception

try:
    process_file("data.txt") # Assume data.txt contains non-numeric data
except RuntimeError as e:
    print(f"Runtime Error: {e}")
    print(f"Caused by: {e.__cause__}") # Access the chained exception (__cause__)
```

**Diagrammatic Representation of Exception Chaining:**

```
[Exception Chaining - Linking Error Messages] 🔗
    ├── Implicit Chaining: Automatic chaining when raising in except block (context). 🔄
    ├── Explicit Chaining (raise ... from ...): Deliberate chaining, set __cause__. 🔗➡️
    ├── __cause__: Direct cause of the exception. 🔗➡️
    └── __context__: Contextual relationship, exception being handled. 🔄

[Analogy - Error Message Chain] 🔗
    Error 1 (FileNotFoundError) -> Handling attempt -> Error 2 (IOError)
    Chain: Error 2 (IOError) is linked to Error 1 (FileNotFoundError) - Error 2 happened because of Error 1.

[Example Chain in Code]
    try: ... except FileNotFoundError as e: raise RuntimeError(...) from e
    RuntimeError.__cause__  points to the original FileNotFoundError. 🔗➡️
```

**Emoji Summary for Exception Chaining:** 🔗 Linking errors,  🔄 Implicit chaining (context),  🔗➡️ Explicit chaining (cause),  __cause__ Direct cause,  __context__ Contextual relation,  📚 Better error context,  🐛 Easier debugging.

### 8.6. User-defined Exceptions

You can create your own **user-defined exceptions** by creating new exception classes. This is useful for defining specific exception types that are relevant to your application or library, making error handling more precise and meaningful.  Think of user-defined exceptions as **"custom alarm types 🚨"** tailored to your program's specific needs.

**Creating User-defined Exception Classes:**

User-defined exception classes are typically created by inheriting from the built-in `Exception` class or one of its subclasses (like `ValueError`, `TypeError`, `RuntimeError`, etc.). By convention, exception class names should end with "Error".

```python
class CustomError(Exception): # Inherit from Exception
    """Base class for custom exceptions in this module."""
    pass

class SpecificError(CustomError): # Inherit from a custom base exception
    """Specific error condition in the application."""
    def __init__(self, message, detail):
        super().__init__(message) # Call superclass constructor to set message
        self.detail = detail # Add custom attribute 'detail'
```

**Using User-defined Exceptions:**

You can raise and handle user-defined exceptions just like built-in exceptions.

```python
def process_data(data):
    if not isinstance(data, dict):
        raise TypeError("Input data must be a dictionary") # Built-in exception
    if 'value' not in data:
        raise SpecificError("Data missing 'value' key", "Key 'value' is required in input dictionary") # User-defined exception
    return data['value']

try:
    data = {'name': 'Example'} # Missing 'value' key, and not a dictionary
    process_data(data)
except TypeError as te:
    print(f"Type Error: {te}")
except SpecificError as se:
    print(f"Specific Error: {se}, Detail: {se.detail}")
```

**Benefits of User-defined Exceptions:**

*   **Clarity and Specificity:**  Make error types more descriptive and relevant to your domain.
*   **Improved Error Handling:**  Allows for more granular and specific exception handling, as you can `except` specific user-defined exception types.
*   **Code Organization:**  Helps in organizing and categorizing errors in your application.
*   **Better Documentation:** User-defined exceptions, especially with docstrings, can serve as documentation of potential error conditions in your code.

**Analogy: User-defined Exceptions as Custom Alarm Types 🚨**

Imagine user-defined exceptions as creating custom alarm types for a complex system, beyond the generic "alarm" signal:

*   **Generic "Alarm" (Built-in `Exception`):** Like a general alarm sound that just indicates "something is wrong."
*   **Custom Alarms (User-defined Exceptions):** Creating specific alarm types, like "Low Fuel Alarm" (SpecificError), "Engine Overheat Alarm" (AnotherSpecificError), etc. These custom alarms provide more precise information about the nature of the problem.

**Diagrammatic Representation of User-defined Exceptions:**

```
[User-defined Exceptions - Custom Alarm Types] 🚨
    ├── Create new exception classes by inheriting from Exception or its subclasses. 👨‍💻
    ├── Class names conventionally end with "Error". 🏷️Error
    ├── Used to define application-specific error conditions. ✨
    └── Allow more precise and meaningful error handling. ✅🛠️

[Example - Defining CustomError and SpecificError]
    class CustomError(Exception): pass  <- Base custom exception
    class SpecificError(CustomError):  <- Specific error type, inherits from CustomError
        def __init__(self, message, detail): ... <- Can add custom attributes

[Benefits] ✨
    ├── Clarity and Specificity: More descriptive error types. 🏷️✅
    ├── Improved Error Handling: Granular except blocks. 🛠️🎯
    ├── Code Organization: Categorize errors. 🗂️
    └── Better Documentation: Docstrings for error conditions. 📚
```

**Emoji Summary for User-defined Exceptions:** 🚨 Custom alarms,  👨‍💻 User-defined classes,  🏷️Error Naming convention,  ✨ Specific error types,  ✅🛠️ Precise handling,  🗂️ Code organization,  📚 Documentation.

### 8.7. Defining Clean-up Actions (`finally` clause)

The `finally` clause in a `try...except...finally` block is used to define **clean-up actions** that must be executed **regardless of whether an exception occurred or not, and whether the exception was handled or not**.  Think of `finally` as **"guaranteed cleanup protocols 🧹🧼"** ensuring resources are released and states are reset, no matter what happens in the `try` block.

**Purpose of `finally`:**

*   **Resource Release:** Primarily used to release resources that were acquired in the `try` block, such as closing files, releasing network connections, freeing memory, etc.
*   **Guaranteed Execution:** Code in the `finally` block is guaranteed to run even if:
    *   No exception occurred in the `try` block.
    *   An exception occurred and was handled in an `except` block.
    *   An exception occurred and was *not* handled (propagated upwards).
    *   `break`, `continue`, or `return` statements are used within the `try` or `except` blocks.

**`finally` Clause Structure:**

```python
try:
    # Risky code that might acquire resources
    resource = acquire_resource()
    # ... code using resource ...
except ExceptionType:
    # Handle exception
    pass
finally:
    # Cleanup actions - always executed
    if resource:
        release_resource(resource) # Ensure resource is released
```

**Analogy: `finally` as Guaranteed Cleanup Protocols 🧹🧼**

Imagine `finally` as setting up guaranteed cleanup protocols after a task, like cleaning up after cooking in a kitchen 🧹🧼:

1.  **`try:` (Cooking Task):** "Try to cook a meal (risky operations that might acquire resources – ingredients, cooking utensils)."
2.  **`except:` (If Cooking Problem):** "If something goes wrong during cooking (e.g., food burns, ingredient missing), handle the problem (try to salvage, order takeout)."
3.  **`finally:` (Cleanup Kitchen - Always):** "Regardless of whether the cooking was successful or if problems occurred, *always clean up the kitchen* afterwards (finally block) – wash dishes, put away ingredients, wipe counters. This cleanup must happen no matter what."

**Example - File Handling with `finally`:**

```python
file = None # Initialize file variable outside try block
try:
    file = open("my_file.txt", "r") # Acquire file resource
    content = file.read()
    print(content)
    # ... process content ...
except FileNotFoundError:
    print("File not found!")
except Exception as e: # Catch other exceptions
    print(f"An error occurred: {e}")
finally:
    if file: # Check if file was successfully opened
        file.close() # Release file resource (close file) - guaranteed cleanup
    print("File handling complete (cleanup done).")
```

**Diagrammatic Representation of `finally` Clause:**

```
[finally Clause - Guaranteed Cleanup] 🧹🧼
    ├── Defines cleanup actions that ALWAYS execute. ✅
    ├── Resource Release: Close files, release connections, free memory. ♻️
    ├── Guaranteed Execution: Runs regardless of exceptions, handling, or control flow. 🛡️
    └── Essential for resource management and ensuring consistent program state. 🧹

[Analogy - Kitchen Cleanup After Cooking] 🧹🧼🍽️
    Cooking (try block) -> Possible problems (except blocks) -> ALWAYS Cleanup Kitchen (finally block)

[Example - File Handling Cleanup in finally]
    try: file = open(...) ... except ... finally: if file: file.close() <- Guaranteed file closure.
```

**Emoji Summary for `finally` Clause:** 🧹🧼 Guaranteed cleanup,  ✅ Always execute,  ♻️ Resource release,  🛡️ Consistent execution,  🍽️ Kitchen cleanup analogy,  🔒 Resource management.

### 8.8. Predefined Clean-up Actions (`with` statement)

The `with` statement in Python provides a more elegant and concise way to ensure cleanup actions, especially for resources like files. It works with objects that support the **context management protocol** (objects that have `__enter__` and `__exit__` methods).  Think of `with` statement as **"automatic cleanup context 🔒"** that simplifies resource management.

**`with` Statement Structure:**

```python
with expression as variable:
    # Block of code where the resource is used
    # ... operations with variable ...
# Resource is automatically cleaned up when the block exits
```

*   **`with expression as variable:`:**  `expression` should evaluate to an object that supports context management (e.g., file object from `open()`, network connection, locks, etc.). The `as variable` part is optional; it assigns the object to `variable` for use within the `with` block.
*   **Indented Block:** Code within the `with` block operates within the context managed by the object.
*   **Automatic Cleanup:** When the `with` block is exited (either normally or due to an exception), the `__exit__` method of the object is automatically called, which typically performs cleanup actions (like closing files, releasing locks).

**Analogy: `with` Statement as Automatic Cleanup Context 🔒**

Imagine `with` statement as setting up an automatic cleanup context, like using a self-cleaning appliance or a context-aware tool 🔒:

1.  **`with open(...) as file_object:` (Enter Context):** "Enter a special context for file operations, automatically managing the file (like opening a self-cleaning oven 🔒)."
2.  **`# ... file operations ...` (Work within Context):** "Perform file operations within this context (cook in the self-cleaning oven 🔒)."
3.  **Exit Context (Automatic Cleanup):** "When done with the block (cooking is finished), the context automatically handles cleanup (self-cleaning cycle starts 🔒, oven is cleaned and switched off automatically)." – File is automatically closed by `__exit__` method.

**Example - File Handling with `with` statement (cleaner and recommended):**

```python
with open("my_file.txt", "r") as file: # Open file in 'with' context
    content = file.read()
    print(content)
    # File is automatically closed when 'with' block ends - automatic cleanup!

# File is already closed here, even if exceptions occurred in the 'with' block
```

**Benefits of `with` Statement:**

*   **Automatic Resource Management:** Ensures resources are always properly cleaned up, even in case of exceptions. ✅
    *   **Code Clarity:**  Makes code cleaner and easier to read by clearly delineating the scope where a resource is used and managed.
*   **Reduced Boilerplate:**  Avoids the need for explicit `finally` blocks for simple cleanup, making code more concise.
*   **Exception Safety:**  Provides exception safety – cleanup is guaranteed even if exceptions occur.

**Diagrammatic Representation of `with` Statement:**

```
[with Statement - Automatic Cleanup Context] 🔒
    ├── Automatic Resource Management: Ensures cleanup via context management protocol. ✅
    ├── __enter__() method: Called when entering 'with' block (setup). ⬆️
    ├── __exit__(exc_type, exc_val, exc_tb) method: Called when exiting 'with' block (cleanup). ⬇️🧹
    └── Cleaner and more concise code for resource handling. ✨

[Analogy - Self-Cleaning Appliance] 🔒
    with open(...) as file:  ->  Enter self-cleaning context 🔒
        # ... operations ... -> Work within context (appliance in use 🔒)
    # Automatic cleanup when exiting 'with' block (self-cleaning cycle starts 🔒, appliance switches off).

[Example - File Handling with 'with']
    with open("file.txt", "r") as f: # __enter__() called when entering 'with'
        # ... file operations ...
    # __exit__() called automatically when exiting 'with' - file closed. ⬇️🧹
```

**Emoji Summary for `with` Statement:** 🔒 Automatic cleanup,  ✅ Resource management,  ⬆️ `__enter__` (setup),  ⬇️🧹 `__exit__` (cleanup),  ✨ Cleaner code,  🛡️ Exception safety,  🔒 Self-cleaning context.

### 8.9. Raising and Handling Multiple Unrelated Exceptions (Exception Groups, `except*`)

In modern Python (Python 3.11+), there are features to handle situations where **multiple, unrelated exceptions** might occur and need to be managed together. This is particularly useful in concurrent or asynchronous programming.  Python introduces **Exception Groups** and the `except*` syntax for this purpose.

**Exception Groups:**

An **Exception Group** is a special type of exception that can contain a group of other exceptions. It's like a "bundle of errors" 📦💥💥💥.  You create an ExceptionGroup using `except*` or by explicitly creating an `ExceptionGroup` object.

**`except*` Syntax for Handling Exception Groups:**

The `except*` syntax is used to handle specific types of exceptions *within* an Exception Group. It allows you to handle different types of exceptions from the group separately.

**Example:**

```python
def task1(): raise ValueError("Task 1 failed")
def task2(): raise TypeError("Task 2 failed")
def task3(): return "Task 3 success"

exceptions = []
results = []

for task in [task1, task2, task3]:
    try:
        results.append(task())
    except Exception as e:
        exceptions.append(e)

if exceptions:
    raise ExceptionGroup("Multiple task failures", exceptions) # Create ExceptionGroup

try:
    # ... code that might raise ExceptionGroup ...
    process_tasks() # Example function that might raise ExceptionGroup
except* ValueError as ve: # Handle ValueError exceptions within the group
    print("Handling ValueError group:")
    for e in ve.exceptions:
        print(f"  ValueError: {e}")
except* TypeError as te: # Handle TypeError exceptions within the group
    print("Handling TypeError group:")
    for e in te.exceptions:
        print(f"  TypeError: {e}")
except ExceptionGroup as eg: # Catch any remaining ExceptionGroup (or bare 'except ExceptionGroup:')
    print(f"Unhandled exceptions in group: {eg.exceptions}")
```

**Analogy: Exception Groups as "Bundle of Error Reports" 📦💥💥💥**

Imagine Exception Groups as a way to bundle multiple error reports together, especially from parallel processes or tasks:

1.  **Multiple Tasks (Parallel Processes):** Several tasks are running concurrently.
2.  **Multiple Errors (Error Reports):** Each task might generate an error, leading to multiple error reports.
3.  **Exception Group (Bundle Error Reports):** An Exception Group is like a folder or bundle 📦💥💥💥 that collects all these individual error reports together.
4.  **`except*` (Handle Specific Report Types):** `except*` is like sorting through the bundle and handling specific types of reports separately (e.g., handle all "ValueError reports" first, then all "TypeError reports").

**Diagrammatic Representation of Exception Groups and `except*`:**

```
[Exception Groups - Bundle of Error Reports] 📦💥💥💥
    ├── ExceptionGroup: Container for multiple exceptions. 📦
    ├── Useful for handling multiple unrelated exceptions (e.g., from concurrent tasks). 🤝
    ├── except* ExceptionType as var: Syntax to handle specific exception types within a group. 🎯
    └── Allows granular handling of exceptions within a group. ✅

[Analogy - Bundle of Error Reports from Tasks] 📦💥💥💥
    Task 1 Error -> Report 1
    Task 2 Error -> Report 2
    Task 3 Success -> No report
    ExceptionGroup -> Bundle of [Report 1, Report 2]

[except* Syntax - Handle Specific Report Types in Bundle] 🎯
    except* ValueError as ve: # Handle ValueError reports
        for e in ve.exceptions: ...
    except* TypeError as te:  # Handle TypeError reports
        for e in te.exceptions: ...
```

**Emoji Summary for Exception Groups and `except*`:** 📦💥💥💥 Bundle of errors,  🤝 Multiple exceptions,  except* Handle group,  🎯 Specific type handling,  ✅ Granular control,  Concurrent/async error management.

### 8.10. Enriching Exceptions with Notes (`add_note()` method)

In Python 3.11+, exceptions can be enriched with **notes** using the `add_note()` method. This allows you to add contextual information or details to an exception object without changing its type or message.  Think of adding notes as **"attaching sticky notes 📝 to an error report"** to provide extra context.

**`add_note()` Method:**

The `add_note(note_string)` method can be called on any exception object to add a string as a note. Multiple notes can be added to the same exception.  Notes are stored in the `__notes__` attribute of the exception object (as a list of strings).

**Example:**

```python
def process_value(value):
    try:
        if value < 0:
            raise ValueError("Value cannot be negative")
        return value * 2
    except ValueError as e:
        e.add_note(f"Input value was: {value}") # Add note to the exception
        raise # Re-raise the exception (with the note added)

try:
    process_value(-5)
except ValueError as e:
    print(f"ValueError: {e}")
    if e.__notes__:
        print("Notes:")
        for note in e.__notes__:
            print(f"  - {note}")
```

**Analogy: Enriching Exceptions with Notes as Sticky Notes 📝**

Imagine enriching exceptions with notes as attaching sticky notes to an error report:

1.  **Exception (Error Report):** An exception object is like an error report, indicating a problem.
2.  **`add_note(note_string)` (Add Sticky Note):**  Using `add_note()` is like attaching a sticky note 📝 to the error report with additional details, context, or observations.
3.  **`__notes__` Attribute (Notes on Report):** The `__notes__` attribute is like a collection of sticky notes attached to the report, providing extra information.

**Benefits of Exception Notes:**

*   **Adding Context:**  Provide more contextual information without changing the exception type or main error message.
*   **Non-Intrusive Enrichment:** Notes are separate from the main exception message, keeping the core error clear while adding details.
*   **Debugging Aid:**  Notes can be very helpful for debugging by providing extra information about the state or conditions at the time of the exception.

**Diagrammatic Representation of Exception Notes:**

```
[Enriching Exceptions with Notes - Sticky Notes] 📝
    ├── add_note(note_string): Method to add a note to an exception object. 📝➕
    ├── __notes__ attribute: List of note strings attached to the exception. 📝📝📝
    ├── Provides contextual information without changing exception type/message. ✨
    └── Useful for debugging and adding details to error reports. 🐛

[Analogy - Sticky Notes on Error Report] 📝
    Exception Object -> Error Report
    add_note()       -> Attach Sticky Note 📝 to report
    __notes__        -> Collection of Sticky Notes on Report 📝📝📝

[Example - Adding Note to ValueError]
    except ValueError as e: e.add_note(f"Input value was: {value}") <- Add note to exception object.
```

**Emoji Summary for Exception Notes:** 📝 Sticky notes,  📝➕ `add_note()`,  📝📝📝 `__notes__` attribute,  ✨ Add context,  🐛 Debugging aid,  ℹ️ Extra information.

**In Conclusion:**

This comprehensive section on "Errors and Exceptions" has equipped you with a deep understanding of how to handle runtime problems gracefully in Python. You've learned about:

*   **Syntax Errors:** Grammatical mistakes caught during parsing. ✍️
*   **Exceptions:** Runtime errors that disrupt program flow. 💥
*   **`try...except` for exception handling:** Interception and recovery. 🛠️🚑
*   **`raise` statement for intentional exception triggering:** Signaling errors. 🚨
*   **Exception Chaining:** Linking related exceptions for better context. 🔗
*   **User-defined Exceptions:** Creating custom error types. 🚨
*   **`finally` clause for guaranteed cleanup:** Resource release. 🧹🧼
*   **`with` statement for predefined cleanup actions:** Automatic context management. 🔒
*   **Exception Groups and `except*`:** Handling multiple unrelated exceptions. 📦💥💥💥
*   **Exception Notes (`add_note()`):** Enriching exceptions with contextual information. 📝

With this robust knowledge of error and exception handling, you can now write more resilient, reliable, and maintainable Python programs that gracefully manage unexpected situations and provide valuable debugging information.  You are now a master of error management in Python! 🚀🎉  Ready to explore more advanced Python topics? Let me know!